Workbook
Name CustomerIDList: 'Raw Data'!$A$2:$A$7044

Sheet Dashboard
A1: 📊 Telco Customer Analytics Dashboard
A3: Based on 7,043 real telecom customer records | Source: IBM Telco Customer Churn dataset
B5: Total Customers | E5: Overall Churn Rate | H5: Avg Monthly Charges | K5: Total Monthly Revenue | N5: Fabric Optic Adoption | Q5: Avg Tenure (Months) | T5: Senior Citizen %
B6: =COUNTA('Raw Data'!A2:A7044) -> 7043 | E6: =COUNTIF('Raw Data'!U2:U7044,"Yes")/B6 -> 0.26536987 | H6: =AVERAGE('Raw Data'!S2:S7044) -> 64.761692 | K6: =SUM('Raw Data'!S2:S7044) -> 456116.6 | N6: =COUNTIF('Raw Data'!I2:I7044,"Fiber optic")/B6 -> 0.4395854 | Q6: =AVERAGE('Raw Data'!F2:F7044) -> 32.371149 | T6: =COUNTIF('Raw Data'!C2:C7044,1)/B6 -> 0.16214681

Sheet Customer Lookup
A1: 🔍 Customer Lookup Tool
A2: Select Customer ID: | B2: 0480-KYJVA
A4: Gender | B4: =INDEX('Raw Data'!B:B,MATCH($B$2,'Raw Data'!A:A,0)) -> Female
A5: Senior Citizen | B5: =IF(INDEX('Raw Data'!C:C,MATCH($B$2,'Raw Data'!A:A,0))=1,"Yes","No") -> No
A6: Tenure (Months) | B6: =INDEX('Raw Data'!F:F,MATCH($B$2,'Raw Data'!A:A,0)) -> 72
A7: Tenure Group | B7: =INDEX(Analysis!H:H,MATCH($B$2,Analysis!A:A,0)) -> Veteran (49+ mo)
A8: Contract | B8: =INDEX('Raw Data'!P:P,MATCH($B$2,'Raw Data'!A:A,0)) -> Two year
A9: Internet Service | B9: =INDEX('Raw Data'!I:I,MATCH($B$2,'Raw Data'!A:A,0)) -> No
A10: Payment Method | B10: =INDEX('Raw Data'!R:R,MATCH($B$2,'Raw Data'!A:A,0)) -> Credit card (automatic)
A11: Monthly Charges | B11: =INDEX('Raw Data'!S:S,MATCH($B$2,'Raw Data'!A:A,0)) -> 24.25
A12: Total Charges | B12: =INDEX(Analysis!G:G,MATCH($B$2,Analysis!A:A,0)) -> 1784.5
A13: Services Subscribed | B13: =INDEX(Analysis!I:I,MATCH($B$2,Analysis!A:A,0)) -> 2
A14: Risk Tier | B14: =INDEX(Analysis!L:L,MATCH($B$2,Analysis!A:A,0)) -> Low Risk
A15: Churn Status | B15: =INDEX('Raw Data'!U:U,MATCH($B$2,'Raw Data'!A:A,0)) -> No
A18: Profile Summary
A19: =_xlfn.TEXTJOIN(" ",TRUE,"Customer",B2,"has been with the company for",B6,"months on a",B8,"contract with",B9,"internet, subscribing to",B13,"services. Current risk tier:",B14&".") -> Customer 0480-KYJVA has been with the company for 72 months on a Two year contract with No internet, subscribing to 2 services. Current risk tier: Low Risk.

Sheet Summary Tables
A1: Contract Type | B1: Customers | C1: Churned | D1: Churn Rate
A2: Month-to-month | B2: =COUNTIF(Analysis!$C$2:$C$7044,A2) -> 3875 | C2: =COUNTIFS(Analysis!$C$2:$C$7044,A2,Analysis!$K$2:$K$7044,"Yes") -> 1655 | D2: =C2/B2 -> 0.42709677
A3: One year | B3: =COUNTIF(Analysis!$C$2:$C$7044,A3) -> 1473 | C3: =COUNTIFS(Analysis!$C$2:$C$7044,A3,Analysis!$K$2:$K$7044,"Yes") -> 166 | D3: =C3/B3 -> 0.11269518
A4: Two year | B4: =COUNTIF(Analysis!$C$2:$C$7044,A4) -> 1695 | C4: =COUNTIFS(Analysis!$C$2:$C$7044,A4,Analysis!$K$2:$K$7044,"Yes") -> 48 | D4: =C4/B4 -> 0.028318584
A5: TOTAL | B5: =SUM(B2:B4) -> 7043 | C5: =SUM(C2:C4) -> 1869 | D5: =C5/B5 -> 0.26536987
A8: Internet Service | B8: Customers | C8: Churned | D8: Churn Rate | E8: Avg Monthly Charges
A9: Fiber optic | B9: =COUNTIF(Analysis!$D$2:$D$7044,A9) -> 3096 | C9: =COUNTIFS(Analysis!$D$2:$D$7044,A9,Analysis!$K$2:$K$7044,"Yes") -> 1297 | D9: =C9/B9 -> 0.41892765 | E9: =AVERAGEIFS(Analysis!$F$2:$F$7044,Analysis!$D$2:$D$7044,A9) -> 91.500129
A10: DSL | B10: =COUNTIF(Analysis!$D$2:$D$7044,A10) -> 2421 | C10: =COUNTIFS(Analysis!$D$2:$D$7044,A10,Analysis!$K$2:$K$7044,"Yes") -> 459 | D10: =C10/B10 -> 0.18959108 | E10: =AVERAGEIFS(Analysis!$F$2:$F$7044,Analysis!$D$2:$D$7044,A10) -> 58.102169
A11: No | B11: =COUNTIF(Analysis!$D$2:$D$7044,A11) -> 1526 | C11: =COUNTIFS(Analysis!$D$2:$D$7044,A11,Analysis!$K$2:$K$7044,"Yes") -> 113 | D11: =C11/B11 -> 0.074049803 | E11: =AVERAGEIFS(Analysis!$F$2:$F$7044,Analysis!$D$2:$D$7044,A11) -> 21.079194
A14: Tenure Group | B14: Customers | C14: Avg Monthly Charges | D14: Avg Total Charges | E14: Churn Rate
A15: New (0-12 mo) | B15: =COUNTIF(Analysis!$H$2:$H$7044,A15) -> 2186 | C15: =AVERAGEIFS(Analysis!$F$2:$F$7044,Analysis!$H$2:$H$7044,A15) -> 56.097781 | D15: =AVERAGEIFS(Analysis!$G$2:$G$7044,Analysis!$H$2:$H$7044,A15) -> 275.2296 | E15: =COUNTIFS(Analysis!$H$2:$H$7044,A15,Analysis!$K$2:$K$7044,"Yes")/B15 -> 0.47438243
A16: Established (13-24 mo) | B16: =COUNTIF(Analysis!$H$2:$H$7044,A16) -> 1024 | C16: =AVERAGEIFS(Analysis!$F$2:$F$7044,Analysis!$H$2:$H$7044,A16) -> 61.357275 | D16: =AVERAGEIFS(Analysis!$G$2:$G$7044,Analysis!$H$2:$H$7044,A16) -> 1126.2575 | E16: =COUNTIFS(Analysis!$H$2:$H$7044,A16,Analysis!$K$2:$K$7044,"Yes")/B16 -> 0.28710938
A17: Loyal (25-48 mo) | B17: =COUNTIF(Analysis!$H$2:$H$7044,A17) -> 1594 | C17: =AVERAGEIFS(Analysis!$F$2:$F$7044,Analysis!$H$2:$H$7044,A17) -> 65.930552 | D17: =AVERAGEIFS(Analysis!$G$2:$G$7044,Analysis!$H$2:$H$7044,A17) -> 2390.4519 | E17: =COUNTIFS(Analysis!$H$2:$H$7044,A17,Analysis!$K$2:$K$7044,"Yes")/B17 -> 0.20388959
A18: Veteran (49+ mo) | B18: =COUNTIF(Analysis!$H$2:$H$7044,A18) -> 2239 | C18: =AVERAGEIFS(Analysis!$F$2:$F$7044,Analysis!$H$2:$H$7044,A18) -> 73.945377 | D18: =AVERAGEIFS(Analysis!$G$2:$G$7044,Analysis!$H$2:$H$7044,A18) -> 4685.5064 | E18: =COUNTIFS(Analysis!$H$2:$H$7044,A18,Analysis!$K$2:$K$7044,"Yes")/B18 -> 0.095131755
A21: Payment Method | B21: Customers | C21: Churned | D21: Churn Rate
A22: Electronic check | B22: =COUNTIF(Analysis!$E$2:$E$7044,A22) -> 2365 | C22: =COUNTIFS(Analysis!$E$2:$E$7044,A22,Analysis!$K$2:$K$7044,"Yes") -> 1071 | D22: =C22/B22 -> 0.45285412
A23: Mailed check | B23: =COUNTIF(Analysis!$E$2:$E$7044,A23) -> 1612 | C23: =COUNTIFS(Analysis!$E$2:$E$7044,A23,Analysis!$K$2:$K$7044,"Yes") -> 308 | D23: =C23/B23 -> 0.191067
A24: Bank transfer (automatic) | B24: =COUNTIF(Analysis!$E$2:$E$7044,A24) -> 1544 | C24: =COUNTIFS(Analysis!$E$2:$E$7044,A24,Analysis!$K$2:$K$7044,"Yes") -> 258 | D24: =C24/B24 -> 0.16709845
A25: Credit card (automatic) | B25: =COUNTIF(Analysis!$E$2:$E$7044,A25) -> 1522 | C25: =COUNTIFS(Analysis!$E$2:$E$7044,A25,Analysis!$K$2:$K$7044,"Yes") -> 232 | D25: =C25/B25 -> 0.15243101
A28: Risk Tier | B28: Customers | C28: Churn Rate
A29: High Risk | B29: =COUNTIF(Analysis!$L$2:$L$7044,A29) -> 1994 | C29: =COUNTIFS(Analysis!$L$2:$L$7044,A29,Analysis!$K$2:$K$7044,"Yes")/B29 -> 0.51354062
A30: Medium Risk | B30: =COUNTIF(Analysis!$L$2:$L$7044,A30) -> 737 | C30: =COUNTIFS(Analysis!$L$2:$L$7044,A30,Analysis!$K$2:$K$7044,"Yes")/B30 -> 0.37720488
A31: Low-Medium Risk | B31: =COUNTIF(Analysis!$L$2:$L$7044,A31) -> 1144 | C31: =COUNTIFS(Analysis!$L$2:$L$7044,A31,Analysis!$K$2:$K$7044,"Yes")/B31 -> 0.30856643
A32: Low Risk | B32: =COUNTIF(Analysis!$L$2:$L$7044,A32) -> 3168 | C32: =COUNTIFS(Analysis!$L$2:$L$7044,A32,Analysis!$K$2:$K$7044,"Yes")/B32 -> 0.067550505

Sheet Analysis
A1: Customer ID | B1: Tenure | C1: Contract | D1: Internet Service | E1: Payment Method | F1: Monthly Charges | G1: Total Charges (Cleaned) | H1: Tenure Group | I1: Services Subscribed | J1: Estimated Join Date | K1: Churn | L1: Risk Tier
A2: ='Raw Data'!A2 -> 7590-VHVEG | B2: ='Raw Data'!F2 -> 1 | C2: ='Raw Data'!P2 -> Month-to-month | D2: ='Raw Data'!I2 -> DSL | E2: ='Raw Data'!R2 -> Electronic check | F2: ='Raw Data'!S2 -> 29.85 | G2: =IFERROR(VALUE('Raw Data'!T2),0) -> 29.85 | H2: {=_xlfn.IFS(B2<=12,"New (0-12 mo)",B2<=24,"Established (13-24 mo)",B2<=48,"Loyal (25-48 mo)",TRUE,"Veteran (49+ mo)")} -> New (0-12 mo) | I2: =COUNTIF('Raw Data'!G2:O2,"Yes") -> 1 | J2: =EDATE(TODAY(),-B2) -> 46174 | K2: ='Raw Data'!U2 -> No | L2: =IF(AND(C2="Month-to-month",B2<=12),"High Risk",IF(AND(C2="Month-to-month",B2<=24),"Medium Risk",IF(C2="Month-to-month","Low-Medium Risk","Low Risk"))) -> High Risk
A3: ='Raw Data'!A3 -> 5575-GNVDE | B3: ='Raw Data'!F3 -> 34 | C3: ='Raw Data'!P3 -> One year | D3: ='Raw Data'!I3 -> DSL | E3: ='Raw Data'!R3 -> Mailed check | F3: ='Raw Data'!S3 -> 56.95 | G3: =IFERROR(VALUE('Raw Data'!T3),0) -> 1889.5 | H3: {=_xlfn.IFS(B3<=12,"New (0-12 mo)",B3<=24,"Established (13-24 mo)",B3<=48,"Loyal (25-48 mo)",TRUE,"Veteran (49+ mo)")} -> Loyal (25-48 mo) | I3: =COUNTIF('Raw Data'!G3:O3,"Yes") -> 3 | J3: =EDATE(TODAY(),-B3) -> 45170 | K3: ='Raw Data'!U3 -> No | L3: =IF(AND(C3="Month-to-month",B3<=12),"High Risk",IF(AND(C3="Month-to-month",B3<=24),"Medium Risk",IF(C3="Month-to-month","Low-Medium Risk","Low Risk"))) -> Low Risk
A4: ='Raw Data'!A4 -> 3668-QPYBK | B4: ='Raw Data'!F4 -> 2 | C4: ='Raw Data'!P4 -> Month-to-month | D4: ='Raw Data'!I4 -> DSL | E4: ='Raw Data'!R4 -> Mailed check | F4: ='Raw Data'!S4 -> 53.85 | G4: =IFERROR(VALUE('Raw Data'!T4),0) -> 108.15 | H4: {=_xlfn.IFS(B4<=12,"New (0-12 mo)",B4<=24,"Established (13-24 mo)",B4<=48,"Loyal (25-48 mo)",TRUE,"Veteran (49+ mo)")} -> New (0-12 mo) | I4: =COUNTIF('Raw Data'!G4:O4,"Yes") -> 3 | J4: =EDATE(TODAY(),-B4) -> 46143 | K4: ='Raw Data'!U4 -> Yes | L4: =IF(AND(C4="Month-to-month",B4<=12),"High Risk",IF(AND(C4="Month-to-month",B4<=24),"Medium Risk",IF(C4="Month-to-month","Low-Medium Risk","Low Risk"))) -> High Risk
A5: ='Raw Data'!A5 -> 7795-CFOCW | B5: ='Raw Data'!F5 -> 45 | C5: ='Raw Data'!P5 -> One year | D5: ='Raw Data'!I5 -> DSL | E5: ='Raw Data'!R5 -> Bank transfer (automatic) | F5: ='Raw Data'!S5 -> 42.3 | G5: =IFERROR(VALUE('Raw Data'!T5),0) -> 1840.75 | H5: {=_xlfn.IFS(B5<=12,"New (0-12 mo)",B5<=24,"Established (13-24 mo)",B5<=48,"Loyal (25-48 mo)",TRUE,"Veteran (49+ mo)")} -> Loyal (25-48 mo) | I5: =COUNTIF('Raw Data'!G5:O5,"Yes") -> 3 | J5: =EDATE(TODAY(),-B5) -> 44835 | K5: ='Raw Data'!U5 -> No | L5: =IF(AND(C5="Month-to-month",B5<=12),"High Risk",IF(AND(C5="Month-to-month",B5<=24),"Medium Risk",IF(C5="Month-to-month","Low-Medium Risk","Low Risk"))) -> Low Risk
A6: ='Raw Data'!A6 -> 9237-HQITU | B6: ='Raw Data'!F6 -> 2 | C6: ='Raw Data'!P6 -> Month-to-month | D6: ='Raw Data'!I6 -> Fiber optic | E6: ='Raw Data'!R6 -> Electronic check | F6: ='Raw Data'!S6 -> 70.7 | G6: =IFERROR(VALUE('Raw Data'!T6),0) -> 151.65 | H6: {=_xlfn.IFS(B6<=12,"New (0-12 mo)",B6<=24,"Established (13-24 mo)",B6<=48,"Loyal (25-48 mo)",TRUE,"Veteran (49+ mo)")} -> New (0-12 mo) | I6: =COUNTIF('Raw Data'!G6:O6,"Yes") -> 1 | J6: =EDATE(TODAY(),-B6) -> 46143 | K6: ='Raw Data'!U6 -> Yes | L6: =IF(AND(C6="Month-to-month",B6<=12),"High Risk",IF(AND(C6="Month-to-month",B6<=24),"Medium Risk",IF(C6="Month-to-month","Low-Medium Risk","Low Risk"))) -> High Risk
A7: ='Raw Data'!A7 -> 9305-CDSKC | B7: ='Raw Data'!F7 -> 8 | C7: ='Raw Data'!P7 -> Month-to-month | D7: ='Raw Data'!I7 -> Fiber optic | E7: ='Raw Data'!R7 -> Electronic check | F7: ='Raw Data'!S7 -> 99.65 | G7: =IFERROR(VALUE('Raw Data'!T7),0) -> 820.5 | H7: {=_xlfn.IFS(B7<=12,"New (0-12 mo)",B7<=24,"Established (13-24 mo)",B7<=48,"Loyal (25-48 mo)",TRUE,"Veteran (49+ mo)")} -> New (0-12 mo) | I7: =COUNTIF('Raw Data'!G7:O7,"Yes") -> 5 | J7: =EDATE(TODAY(),-B7) -> 45962 | K7: ='Raw Data'!U7 -> Yes | L7: =IF(AND(C7="Month-to-month",B7<=12),"High Risk",IF(AND(C7="Month-to-month",B7<=24),"Medium Risk",IF(C7="Month-to-month","Low-Medium Risk","Low Risk"))) -> High Risk
A8: ='Raw Data'!A8 -> 1452-KIOVK | B8: ='Raw Data'!F8 -> 22 | C8: ='Raw Data'!P8 -> Month-to-month | D8: ='Raw Data'!I8 -> Fiber optic | E8: ='Raw Data'!R8 -> Credit card (automatic) | F8: ='Raw Data'!S8 -> 89.1 | G8: =IFERROR(VALUE('Raw Data'!T8),0) -> 1949.4 | H8: {=_xlfn.IFS(B8<=12,"New (0-12 mo)",B8<=24,"Established (13-24 mo)",B8<=48,"Loyal (25-48 mo)",TRUE,"Veteran (49+ mo)")} -> Established (13-24 mo) | I8: =COUNTIF('Raw Data'!G8:O8,"Yes") -> 4 | J8: =EDATE(TODAY(),-B8) -> 45536 | K8: ='Raw Data'!U8 -> No | L8: =IF(AND(C8="Month-to-month",B8<=12),"High Risk",IF(AND(C8="Month-to-month",B8<=24),"Medium Risk",IF(C8="Month-to-month","Low-Medium Risk","Low Risk"))) -> Medium Risk
A9: ='Raw Data'!A9 -> 6713-OKOMC | B9: ='Raw Data'!F9 -> 10 | C9: ='Raw Data'!P9 -> Month-to-month | D9: ='Raw Data'!I9 -> DSL | E9: ='Raw Data'!R9 -> Mailed check | F9: ='Raw Data'!S9 -> 29.75 | G9: =IFERROR(VALUE('Raw Data'!T9),0) -> 301.9 | H9: {=_xlfn.IFS(B9<=12,"New (0-12 mo)",B9<=24,"Established (13-24 mo)",B9<=48,"Loyal (25-48 mo)",TRUE,"Veteran (49+ mo)")} -> New (0-12 mo) | I9: =COUNTIF('Raw Data'!G9:O9,"Yes") -> 1 | J9: =EDATE(TODAY(),-B9) -> 45901 | K9: ='Raw Data'!U9 -> No | L9: =IF(AND(C9="Month-to-month",B9<=12),"High Risk",IF(AND(C9="Month-to-month",B9<=24),"Medium Risk",IF(C9="Month-to-month","Low-Medium Risk","Low Risk"))) -> High Risk
A10: ='Raw Data'!A10 -> 7892-POOKP | B10: ='Raw Data'!F10 -> 28 | C10: ='Raw Data'!P10 -> Month-to-month | D10: ='Raw Data'!I10 -> Fiber optic | E10: ='Raw Data'!R10 -> Electronic check | F10: ='Raw Data'!S10 -> 104.8 | G10: =IFERROR(VALUE('Raw Data'!T10),0) -> 3046.05 | H10: {=_xlfn.IFS(B10<=12,"New (0-12 mo)",B10<=24,"Established (13-24 mo)",B10<=48,"Loyal (25-48 mo)",TRUE,"Veteran (49+ mo)")} -> Loyal (25-48 mo) | I10: =COUNTIF('Raw Data'!G10:O10,"Yes") -> 6 | J10: =EDATE(TODAY(),-B10) -> 45352 | K10: ='Raw Data'!U10 -> Yes | L10: =IF(AND(C10="Month-to-month",B10<=12),"High Risk",IF(AND(C10="Month-to-month",B10<=24),"Medium Risk",IF(C10="Month-to-month","Low-Medium Risk","Low Risk"))) -> Low-Medium Risk
A11: ='Raw Data'!A11 -> 6388-TABGU | B11: ='Raw Data'!F11 -> 62 | C11: ='Raw Data'!P11 -> One year | D11: ='Raw Data'!I11 -> DSL | E11: ='Raw Data'!R11 -> Bank transfer (automatic) | F11: ='Raw Data'!S11 -> 56.15 | G11: =IFERROR(VALUE('Raw Data'!T11),0) -> 3487.95 | H11: {=_xlfn.IFS(B11<=12,"New (0-12 mo)",B11<=24,"Established (13-24 mo)",B11<=48,"Loyal (25-48 mo)",TRUE,"Veteran (49+ mo)")} -> Veteran (49+ mo) | I11: =COUNTIF('Raw Data'!G11:O11,"Yes") -> 3 | J11: =EDATE(TODAY(),-B11) -> 44317 | K11: ='Raw Data'!U11 -> No | L11: =IF(AND(C11="Month-to-month",B11<=12),"High Risk",IF(AND(C11="Month-to-month",B11<=24),"Medium Risk",IF(C11="Month-to-month","Low-Medium Risk","Low Risk"))) -> Low Risk
A12: ='Raw Data'!A12 -> 9763-GRSKD | B12: ='Raw Data'!F12 -> 13 | C12: ='Raw Data'!P12 -> Month-to-month | D12: ='Raw Data'!I12 -> DSL | E12: ='Raw Data'!R12 -> Mailed check | F12: ='Raw Data'!S12 -> 49.95 | G12: =IFERROR(VALUE('Raw Data'!T12),0) -> 587.45 | H12: {=_xlfn.IFS(B12<=12,"New (0-12 mo)",B12<=24,"Established (13-24 mo)",B12<=48,"Loyal (25-48 mo)",TRUE,"Veteran (49+ mo)")} -> Established (13-24 mo) | I12: =COUNTIF('Raw Data'!G12:O12,"Yes") -> 2 | J12: =EDATE(TODAY(),-B12) -> 45809 | K12: ='Raw Data'!U12 -> No | L12: =IF(AND(C12="Month-to-month",B12<=12),"High Risk",IF(AND(C12="Month-to-month",B12<=24),"Medium Risk",IF(C12="Month-to-month","Low-Medium Risk","Low Risk"))) -> Medium Risk
A13: ='Raw Data'!A13 -> 7469-LKBCI | B13: ='Raw Data'!F13 -> 16 | C13: ='Raw Data'!P13 -> Two year | D13: ='Raw Data'!I13 -> No | E13: ='Raw Data'!R13 -> Credit card (automatic) | F13: ='Raw Data'!S13 -> 18.95 | G13: =IFERROR(VALUE('Raw Data'!T13),0) -> 326.8 | H13: {=_xlfn.IFS(B13<=12,"New (0-12 mo)",B13<=24,"Established (13-24 mo)",B13<=48,"Loyal (25-48 mo)",TRUE,"Veteran (49+ mo)")} -> Established (13-24 mo) | I13: =COUNTIF('Raw Data'!G13:O13,"Yes") -> 1 | J13: =EDATE(TODAY(),-B13) -> 45717 | K13: ='Raw Data'!U13 -> No | L13: =IF(AND(C13="Month-to-month",B13<=12),"High Risk",IF(AND(C13="Month-to-month",B13<=24),"Medium Risk",IF(C13="Month-to-month","Low-Medium Risk","Low Risk"))) -> Low Risk
... A7044: ='Raw Data'!A7044 -> 3186-AJIEK | B7044: ='Raw Data'!F7044 -> 66 | C7044: ='Raw Data'!P7044 -> Two year | D7044: ='Raw Data'!I7044 -> Fiber optic | E7044: ='Raw Data'!R7044 -> Bank transfer (automatic) | F7044: ='Raw Data'!S7044 -> 105.65 | G7044: =IFERROR(VALUE('Raw Data'!T7044),0) -> 6844.5 | H7044: {=_xlfn.IFS(B7044<=12,"New (0-12 mo)",B7044<=24,"Established (13-24 mo)",B7044<=48,"Loyal (25-48 mo)",TRUE,"Veteran (49+ mo)")} -> Veteran (49+ mo) | I7044: =COUNTIF('Raw Data'!G7044:O7044,"Yes") -> 6 | J7044: =EDATE(TODAY(),-B7044) -> 44197 | K7044: ='Raw Data'!U7044 -> No | L7044: =IF(AND(C7044="Month-to-month",B7044<=12),"High Risk",IF(AND(C7044="Month-to-month",B7044<=24),"Medium Risk",IF(C7044="Month-to-month","Low-Medium Risk","Low Risk"))) -> Low Risk

Sheet Raw Data
A1: customerID | B1: gender | C1: SeniorCitizen | D1: Partner | E1: Dependents | F1: tenure | G1: PhoneService | H1: MultipleLines | I1: InternetService | J1: OnlineSecurity | K1: OnlineBackup | L1: DeviceProtection | M1: TechSupport | N1: StreamingTV | O1: StreamingMovies | P1: Contract | Q1: PaperlessBilling | R1: PaymentMethod | S1: MonthlyCharges | T1: TotalCharges | U1: Churn | W1: {=SUMPRODUCT(--ISERROR(VALUE(T2:T7044)))} -> 11
A2: 7590-VHVEG | B2: Female | C2: 0 | D2: Yes | E2: No | F2: 1 | G2: No | H2: No phone service | I2: DSL | J2: No | K2: Yes | L2: No | M2: No | N2: No | O2: No | P2: Month-to-month | Q2: Yes | R2: Electronic check | S2: 29.85 | T2: 29.85 | U2: No
A3: 5575-GNVDE | B3: Male | C3: 0 | D3: No | E3: No | F3: 34 | G3: Yes | H3: No | I3: DSL | J3: Yes | K3: No | L3: Yes | M3: No | N3: No | O3: No | P3: One year | Q3: No | R3: Mailed check | S3: 56.95 | T3: 1889.5 | U3: No
A4: 3668-QPYBK | B4: Male | C4: 0 | D4: No | E4: No | F4: 2 | G4: Yes | H4: No | I4: DSL | J4: Yes | K4: Yes | L4: No | M4: No | N4: No | O4: No | P4: Month-to-month | Q4: Yes | R4: Mailed check | S4: 53.85 | T4: 108.15 | U4: Yes
A5: 7795-CFOCW | B5: Male | C5: 0 | D5: No | E5: No | F5: 45 | G5: No | H5: No phone service | I5: DSL | J5: Yes | K5: No | L5: Yes | M5: Yes | N5: No | O5: No | P5: One year | Q5: No | R5: Bank transfer (automatic) | S5: 42.3 | T5: 1840.75 | U5: No
A6: 9237-HQITU | B6: Female | C6: 0 | D6: No | E6: No | F6: 2 | G6: Yes | H6: No | I6: Fiber optic | J6: No | K6: No | L6: No | M6: No | N6: No | O6: No | P6: Month-to-month | Q6: Yes | R6: Electronic check | S6: 70.7 | T6: 151.65 | U6: Yes
A7: 9305-CDSKC | B7: Female | C7: 0 | D7: No | E7: No | F7: 8 | G7: Yes | H7: Yes | I7: Fiber optic | J7: No | K7: No | L7: Yes | M7: No | N7: Yes | O7: Yes | P7: Month-to-month | Q7: Yes | R7: Electronic check | S7: 99.65 | T7: 820.5 | U7: Yes
A8: 1452-KIOVK | B8: Male | C8: 0 | D8: No | E8: Yes | F8: 22 | G8: Yes | H8: Yes | I8: Fiber optic | J8: No | K8: Yes | L8: No | M8: No | N8: Yes | O8: No | P8: Month-to-month | Q8: Yes | R8: Credit card (automatic) | S8: 89.1 | T8: 1949.4 | U8: No
A9: 6713-OKOMC | B9: Female | C9: 0 | D9: No | E9: No | F9: 10 | G9: No | H9: No phone service | I9: DSL | J9: Yes | K9: No | L9: No | M9: No | N9: No | O9: No | P9: Month-to-month | Q9: No | R9: Mailed check | S9: 29.75 | T9: 301.9 | U9: No
A10: 7892-POOKP | B10: Female | C10: 0 | D10: Yes | E10: No | F10: 28 | G10: Yes | H10: Yes | I10: Fiber optic | J10: No | K10: No | L10: Yes | M10: Yes | N10: Yes | O10: Yes | P10: Month-to-month | Q10: Yes | R10: Electronic check | S10: 104.8 | T10: 3046.05 | U10: Yes
A11: 6388-TABGU | B11: Male | C11: 0 | D11: No | E11: Yes | F11: 62 | G11: Yes | H11: No | I11: DSL | J11: Yes | K11: Yes | L11: No | M11: No | N11: No | O11: No | P11: One year | Q11: No | R11: Bank transfer (automatic) | S11: 56.15 | T11: 3487.95 | U11: No
A12: 9763-GRSKD | B12: Male | C12: 0 | D12: Yes | E12: Yes | F12: 13 | G12: Yes | H12: No | I12: DSL | J12: Yes | K12: No | L12: No | M12: No | N12: No | O12: No | P12: Month-to-month | Q12: Yes | R12: Mailed check | S12: 49.95 | T12: 587.45 | U12: No
A13: 7469-LKBCI | B13: Male | C13: 0 | D13: No | E13: No | F13: 16 | G13: Yes | H13: No | I13: No | J13: No internet service | K13: No internet service | L13: No internet service | M13: No internet service | N13: No internet service | O13: No internet service | P13: Two year | Q13: No | R13: Credit card (automatic) | S13: 18.95 | T13: 326.8 | U13: No
... A489: 3649-JPUGY | B489: Male | C489: 0 | D489: No | E489: No | F489: 72 | G489: Yes | H489: Yes | I489: DSL | J489: No | K489: Yes | L489: Yes | M489: Yes | N489: Yes | O489: Yes | P489: Two year | Q489: Yes | R489: Bank transfer (automatic) | S489: 88.6 | T489: 6201.95 | U489: No
A490: 4472-LVYGI | B490: Female | C490: 0 | D490: Yes | E490: Yes | F490: 0 | G490: No | H490: No phone service | I490: DSL | J490: Yes | K490: No | L490: Yes | M490: Yes | N490: Yes | O490: No | P490: Two year | Q490: Yes | R490: Bank transfer (automatic) | S490: 52.55 | U490: No
A491: 8372-JUXUI | B491: Male | C491: 0 | D491: No | E491: Yes | F491: 1 | G491: Yes | H491: Yes | I491: Fiber optic | J491: No | K491: No | L491: No | M491: No | N491: No | O491: No | P491: Month-to-month | Q491: Yes | R491: Electronic check | S491: 74.35 | T491: 74.35 | U491: Yes
A492: 3552-CTCYF | B492: Male | C492: 0 | D492: Yes | E492: Yes | F492: 63 | G492: Yes | H492: Yes | I492: Fiber optic | J492: No | K492: Yes | L492: Yes | M492: No | N492: Yes | O492: Yes | P492: Two year | Q492: Yes | R492: Bank transfer (automatic) | S492: 104.8 | T492: 6597.25 | U492: No
A493: 6778-YSNIH | B493: Female | C493: 0 | D493: No | E493: No | F493: 2 | G493: Yes | H493: No | I493: DSL | J493: No | K493: Yes | L493: No | M493: No | N493: Yes | O493: No | P493: Month-to-month | Q493: Yes | R493: Electronic check | S493: 59 | T493: 114.15 | U493: No
A494: 0388-EOPEX | B494: Female | C494: 0 | D494: Yes | E494: No | F494: 2 | G494: Yes | H494: No | I494: Fiber optic | J494: Yes | K494: No | L494: No | M494: No | N494: No | O494: No | P494: Month-to-month | Q494: Yes | R494: Electronic check | S494: 74.4 | T494: 139.4 | U494: Yes
A495: 5756-OZRIO | B495: Male | C495: 1 | D495: Yes | E495: No | F495: 61 | G495: Yes | H495: Yes | I495: DSL | J495: No | K495: Yes | L495: No | M495: No | N495: No | O495: Yes | P495: One year | Q495: No | R495: Bank transfer (automatic) | S495: 64.05 | T495: 3902.6 | U495: No
A496: 6579-JPICP | B496: Male | C496: 0 | D496: No | E496: No | F496: 1 | G496: Yes | H496: No | I496: No | J496: No internet service | K496: No internet service | L496: No internet service | M496: No internet service | N496: No internet service | O496: No internet service | P496: Month-to-month | Q496: No | R496: Mailed check | S496: 20.4 | T496: 20.4 | U496: No
A497: 8205-OTCHB | B497: Male | C497: 0 | D497: No | E497: No | F497: 22 | G497: No | H497: No phone service | I497: DSL | J497: No | K497: Yes | L497: Yes | M497: No | N497: No | O497: Yes | P497: One year | Q497: Yes | R497: Bank transfer (automatic) | S497: 43.75 | T497: 903.6 | U497: Yes
A498: 4134-BSXLX | B498: Male | C498: 0 | D498: Yes | E498: No | F498: 28 | G498: Yes | H498: No | I498: DSL | J498: Yes | K498: Yes | L498: No | M498: Yes | N498: No | O498: No | P498: Month-to-month | Q498: No | R498: Mailed check | S498: 60.9 | T498: 1785.65 | U498: No
A499: 0505-SPOOW | B499: Female | C499: 0 | D499: Yes | E499: No | F499: 70 | G499: Yes | H499: No | I499: No | J499: No internet service | K499: No internet service | L499: No internet service | M499: No internet service | N499: No internet service | O499: No internet service | P499: Two year | Q499: No | R499: Bank transfer (automatic) | S499: 19.8 | T499: 1397.65 | U499: No
A500: 6235-VDHOM | B500: Female | C500: 1 | D500: No | E500: No | F500: 5 | G500: No | H500: No phone service | I500: DSL | J500: No | K500: Yes | L500: No | M500: No | N500: No | O500: No | P500: Month-to-month | Q500: No | R500: Electronic check | S500: 28.45 | T500: 131.05 | U500: Yes
A501: 7783-YKGDV | B501: Female | C501: 0 | D501: No | E501: No | F501: 12 | G501: Yes | H501: Yes | I501: Fiber optic | J501: Yes | K501: Yes | L501: Yes | M501: No | N501: No | O501: Yes | P501: Month-to-month | Q501: Yes | R501: Bank transfer (automatic) | S501: 99.7 | T501: 1238.45 | U501: Yes
A502: 4374-YMUSQ | B502: Male | C502: 0 | D502: No | E502: No | F502: 34 | G502: Yes | H502: Yes | I502: Fiber optic | J502: Yes | K502: Yes | L502: Yes | M502: Yes | N502: Yes | O502: Yes | P502: One year | Q502: No | R502: Credit card (automatic) | S502: 116.25 | T502: 3899.05 | U502: No
... A754: 1410-RSCMR | B754: Male | C754: 0 | D754: Yes | E754: Yes | F754: 7 | G754: Yes | H754: No | I754: DSL | J754: Yes | K754: No | L754: Yes | M754: Yes | N754: No | O754: Yes | P754: Month-to-month | Q754: Yes | R754: Credit card (automatic) | S754: 71.35 | T754: 515.75 | U754: No
A755: 3115-CZMZD | B755: Male | C755: 0 | D755: No | E755: Yes | F755: 0 | G755: Yes | H755: No | I755: No | J755: No internet service | K755: No internet service | L755: No internet service | M755: No internet service | N755: No internet service | O755: No internet service | P755: Two year | Q755: No | R755: Mailed check | S755: 20.25 | U755: No
A756: 0139-IVFJG | B756: Female | C756: 0 | D756: Yes | E756: No | F756: 2 | G756: Yes | H756: No | I756: Fiber optic | J756: Yes | K756: Yes | L756: No | M756: No | N756: Yes | O756: No | P756: Month-to-month | Q756: No | R756: Electronic check | S756: 90.35 | T756: 190.5 | U756: No
A757: 6683-VLCTZ | B757: Male | C757: 1 | D757: No | E757: No | F757: 20 | G757: Yes | H757: Yes | I757: Fiber optic | J757: No | K757: No | L757: Yes | M757: No | N757: Yes | O757: Yes | P757: Month-to-month | Q757: Yes | R757: Electronic check | S757: 98.55 | T757: 1842.8 | U757: Yes
A758: 5730-DBDSI | B758: Male | C758: 0 | D758: No | E758: No | F758: 66 | G758: Yes | H758: No | I758: No | J758: No internet service | K758: No internet service | L758: No internet service | M758: No internet service | N758: No internet service | O758: No internet service | P758: Two year | Q758: No | R758: Bank transfer (automatic) | S758: 19.7 | T758: 1253.8 | U758: No
A759: 0030-FNXPP | B759: Female | C759: 0 | D759: No | E759: No | F759: 3 | G759: Yes | H759: No | I759: No | J759: No internet service | K759: No internet service | L759: No internet service | M759: No internet service | N759: No internet service | O759: No internet service | P759: Month-to-month | Q759: No | R759: Mailed check | S759: 19.85 | T759: 57.2 | U759: No
A760: 2189-WWOEW | B760: Female | C760: 0 | D760: No | E760: Yes | F760: 15 | G760: Yes | H760: No | I760: Fiber optic | J760: No | K760: Yes | L760: No | M760: No | N760: No | O760: Yes | P760: Month-to-month | Q760: Yes | R760: Bank transfer (automatic) | S760: 85.9 | T760: 1269.55 | U760: Yes
A761: 5684-FJVYR | B761: Female | C761: 0 | D761: Yes | E761: Yes | F761: 72 | G761: Yes | H761: Yes | I761: Fiber optic | J761: Yes | K761: Yes | L761: No | M761: Yes | N761: No | O761: No | P761: Two year | Q761: Yes | R761: Bank transfer (automatic) | S761: 90.35 | T761: 6563.4 | U761: No
A762: 4013-GUXND | B762: Male | C762: 0 | D762: No | E762: No | F762: 1 | G762: Yes | H762: No | I762: No | J762: No internet service | K762: No internet service | L762: No internet service | M762: No internet service | N762: No internet service | O762: No internet service | P762: Month-to-month | Q762: No | R762: Mailed check | S762: 20.8 | T762: 20.8 | U762: No
A763: 1894-IGFSG | B763: Female | C763: 0 | D763: No | E763: No | F763: 22 | G763: Yes | H763: No | I763: Fiber optic | J763: No | K763: No | L763: No | M763: No | N763: Yes | O763: Yes | P763: Month-to-month | Q763: No | R763: Electronic check | S763: 89.25 | T763: 1907.85 | U763: Yes
A764: 7379-POKDZ | B764: Male | C764: 0 | D764: Yes | E764: No | F764: 3 | G764: Yes | H764: No | I764: Fiber optic | J764: No | K764: No | L764: No | M764: No | N764: No | O764: No | P764: Month-to-month | Q764: Yes | R764: Electronic check | S764: 70.3 | T764: 208.85 | U764: Yes
A765: 1266-NZYUI | B765: Female | C765: 0 | D765: Yes | E765: Yes | F765: 72 | G765: Yes | H765: Yes | I765: DSL | J765: Yes | K765: No | L765: Yes | M765: Yes | N765: No | O765: No | P765: Two year | Q765: No | R765: Bank transfer (automatic) | S765: 66.85 | T765: 4758.8 | U765: No
A766: 7969-FFOWG | B766: Male | C766: 0 | D766: Yes | E766: Yes | F766: 65 | G766: Yes | H766: No | I766: No | J766: No internet service | K766: No internet service | L766: No internet service | M766: No internet service | N766: No internet service | O766: No internet service | P766: Two year | Q766: No | R766: Mailed check | S766: 19.9 | T766: 1292.6 | U766: No
...
